Workbook
Name CUSTOMER_DETAILS: #REF!
Name InvoiceDetails: 'INVOICE DETAILS'!$A$2:$AG$1048714
Name CustDetails: 'CUSTOMER DETAILS'!$B$2:$H$1000
Name CustDetail1: 'CUSTOMER DETAILS'!$B$2:$H$1000
Name PRINT: 'CREDIT NOTE'!$A$2:$J$57
Name PRINT: 'INVOICE Other than MH'!$A$2:$J$57
Name PRINT: 'INVOICE Only MH'!$A$2:$J$58
Name InvoiceDetails: 'Copy of INVOICE DETAILS'!$A$2:$AF$1048576

Sheet INVOICE Only MH
B2: TAX INVOICE
B4: MAHALAXMI AGRO ENERGIES | F4: Invoice No. | I4: Dated
B5: 70 Mahakali Nagar 3, Mhalginagar, | F5: =IFERROR(VLOOKUP(F13,InvoiceDetails,11,FALSE)," ") -> 418 | I5: =VLOOKUP(F13,InvoiceDetails,4,FALSE) -> 46102
B6: Hudkeshwar Ring Road, Nagpur 34 | F6: Delivery Note | I6: Payment Mode/Terms
B7: 8550952303 | F7: =IFERROR(VLOOKUP(F13,InvoiceDetails,5,FALSE)," ") -> - | I7: =IFERROR(VLOOKUP(F13,InvoiceDetails,6,FALSE)," ") -> -
B8: GSTN: | C8: 27BOPPP0960N1Z7 | F8: Supplier Ref. | I8: Other Reference(s)
B9: State: | C9: MAHARASHTRA | E9: 440034 | F9: =IFERROR(VLOOKUP(F13,InvoiceDetails,7,FALSE)," ") -> - | I9: =IFERROR(VLOOKUP(#REF!,InvoiceDetails,8,FALSE)," ")
B10: Mail: | C10: biomassenergies@gmail.com | F10: Buyer's Order No. | I10: Dated
B11: Consignee | F11: =IFERROR(VLOOKUP(F13,InvoiceDetails,9,FALSE)," ") -> - | I11: =IFERROR(VLOOKUP(F13,InvoiceDetails,10,FALSE)," ") -> 46102
B12: =VLOOKUP(F13,InvoiceDetails,2,FALSE) -> GAURI,S TAVA TADKA | F12: Despatch Document No | I12: Delivery Note Date
B13: =VLOOKUP(B12,CustDetail1,2,FALSE) -> HARIDARSHAN APARTMENT TRIMURTI NAGAR BESIDE KRISHNA DENTAL CLINIC | F13: MAE060/25-26-0020 | I13: =IFERROR(VLOOKUP(#REF!,InvoiceDetails,12,FALSE)," ")
F15: Despatched Through | I15: Destination
B16: GSTN: | C16: =VLOOKUP(B12,CustDetail1,3,FALSE) | F16: =IFERROR(VLOOKUP(F13,InvoiceDetails,13,FALSE)," ") -> SELF PICKUP | I16: =IFERROR(VLOOKUP(F13,InvoiceDetails,14,FALSE)," ") -> NAGPUR
B17: State: | C17: =VLOOKUP(B12,CustDetail1,4,FALSE) -> MAHARASHTRA | E17: =VLOOKUP(B12,CustDetail1,5,FALSE)
B18: Mail: | C18: =VLOOKUP(B12,CustDetail1,6,FALSE) | F18: Bill of Landing/LR-RR No. | I18: Motor Vehicle Number
F19: =IFERROR(VLOOKUP(#REF!,InvoiceDetails,15,FALSE)," ") | I19: =IFERROR(VLOOKUP(F13,InvoiceDetails,16,FALSE)," ")
B21: Buyer (If Other Than Consignee) | F21: Terms Of Delivery
B22: =VLOOKUP(F13,InvoiceDetails,2,FALSE) -> GAURI,S TAVA TADKA
B23: =VLOOKUP(B22,CustDetail1,2,FALSE) -> HARIDARSHAN APARTMENT TRIMURTI NAGAR BESIDE KRISHNA DENTAL CLINIC
B25: GSTN: | C25: =VLOOKUP(B12,CustDetail1,3,FALSE)
B26: State: | C26: =VLOOKUP(B12,CustDetail1,4,FALSE) -> MAHARASHTRA | E26: =VLOOKUP(B12,CustDetail1,5,FALSE)
B27: Mail: | C27: =VLOOKUP(B12,CustDetail1,6,FALSE)
B28: Sr. No. | C28: Description Of Goods | F28: HSN Code | G28: Quatity | H28: Rate | I28: Per | J28: Amount
B29: 1 | C29: =IFERROR(VLOOKUP(F13,InvoiceDetails,17,FALSE)," ") -> BIOMASS PELLET STOVE 15KG | F29: =IFERROR(VLOOKUP(F13,InvoiceDetails,18,FALSE)," ") | G29: =IFERROR(VLOOKUP(F13,InvoiceDetails,19,FALSE)," ") -> 1 | H29: =IFERROR(VLOOKUP(F13,InvoiceDetails,20,FALSE)," ") -> 19000 | I29: =IFERROR(VLOOKUP(F13,InvoiceDetails,21,FALSE)," ") -> PCS | J29: =IFERROR(VLOOKUP(F13,InvoiceDetails,22,FALSE)," ") -> 19000
E31: SGST OUTPUT @ 2.5% | H31: =IFERROR(VLOOKUP(#REF!,InvoiceDetails,23,FALSE)," ") | J31: =IFERROR(VLOOKUP(F13,InvoiceDetails,30,FALSE)," ") -> 475
E32: CGST OUTPUT @ 2.5% | H32: =IFERROR(VLOOKUP(#REF!,InvoiceDetails,24,FALSE)," ") | J32: =IFERROR(VLOOKUP(F13,InvoiceDetails,31,FALSE)," ") -> 475
E33: ROUNDOFF | J33: =IFERROR(VLOOKUP(F13,InvoiceDetails,27,FALSE)," ") -> 0
E35: TRANSPORTATION | J35: =IFERROR(VLOOKUP(F13,InvoiceDetails,28,FALSE)," ")
E40: Total | G40: =SUM(G29:G39) -> 1 | J40: =IFERROR(VLOOKUP(F13,InvoiceDetails,26,FALSE)," ") -> 19950
B41: Amount Chargeable(in words) | J41: E. & O.E
B42: INR | C42: ="INR"&CHOOSE(LEFT(TEXT(J40,"000000000.00"))+1,,"One","Two","Three","Four","Five","Six","Seven","Eight","Nine") &IF(--LEFT(TEXT(J40,"000000000.00"))=0,,IF(AND(--MID(TEXT(J40,"000000000.00"),2,1)=0,--MID(TEXT(J40,"000000000.00"),3,1)=0)," Hundred"," Hundred and ")) &CHOOSE(MID(TEXT(J40,"000000000.00"),2,1)+1,,,"Twenty ","Thirty ","Forty ","Fifty ","Sixty ","Seventy ","Eighty ","Ninety ") &IF(--MID(TEXT(J40,"000000000.00"),2,1)<>1,CHOOSE(MID(TEXT(J40,"000000000.00"),3,1)+1,,"One","Two","Three","Four","Five","Six","Seven","Eight","Nine"), CHOOSE(MID(TEXT(J40,"000000000.00"),3,1)+1,"Ten","Eleven","Twelve","Thirteen","Fourteen","Fifteen","Sixteen","Seventeen","Eighteen","Nineteen")) &IF((--LEFT(TEXT(J40,"000000000.00"))+MID(TEXT(J40,"000000000.00"),2,1)+MID(TEXT(J40,"000000000.00"),3,1))=0,,IF(AND((--MID(TEXT(J40,"000000000.00"),4,1)+MID(TEXT(J40,"000000000.00"),5,1)+MID(TEXT(J40,"000000000.00"),6,1)+MID(TEXT(J40,"000000000.00"),7,1))=0,(--MID(TEXT(J40,"000000000.00"),8,1)+RIGHT(TEXT(J40,"000000000.00")))>0)," Million and "," Million ")) &CHOOSE(MID(TEXT(J40,"000000000.00"),4,1)+1,,"One","Two","Three","Four","Five","Six","Seven","Eight","Nine") &IF(--MID(TEXT(J40,"000000000.00"),4,1)=0,,IF(AND(--MID(TEXT(J40,"000000000.00"),5,1)=0,--MID(TEXT(J40,"000000000.00"),6,1)=0)," Hundred"," Hundred and")) &CHOOSE(MID(TEXT(J40,"000000000.00"),5,1)+1,,," Twenty"," Thirty"," Forty"," Fifty"," Sixty"," Seventy"," Eighty"," Ninety") &IF(--MID(TEXT(J40,"000000000.00"),5,1)<>1,CHOOSE(MID(TEXT(J40,"000000000.00"),6,1)+1,," One"," Two"," Three"," Four"," Five"," Six"," Seven"," Eight"," Nine"),CHOOSE(MID(TEXT(J40,"000000000.00"),6,1)+1," Ten"," Eleven"," Twelve"," Thirteen"," Fourteen"," Fifteen"," Sixteen"," Seventeen"," Eighteen"," Nineteen")) &IF((--MID(TEXT(J40,"000000000.00"),4,1)+MID(TEXT(J40,"000000000.00"),5,1)+MID(TEXT(J40,"000000000.00"),6,1))=0,,IF(OR((--MID(TEXT(J40,"000000000.00"),7,1)+MID(TEXT(J40,"000000000.00"),8,1)+MID(TEXT(J40,"000000000.00"),9,1))=0,--MID(TEXT(J40,"000000000.00"),7,1)<>0)," Thousand "," Thousand and ")) &CHOOSE(MID(TEXT(J40,"000000000.00"),7,1)+1,,"One","Two","Three","Four","Five","Six","Seven","Eight","Nine") &IF(--MID(TEXT(J40,"000000000.00"),7,1)=0,,IF(AND(--MID(TEXT(J40,"000000000.00"),8,1)=0,--MID(TEXT(J40,"000000000.00"),9,1)=0)," Hundred "," Hundred and "))& CHOOSE(MID(TEXT(J40,"000000000.00"),8,1)+1,,,"Twenty ","Thirty ","Forty ","Fifty ","Sixty ","Seventy ","Eighty ","Ninety ") &IF(--MID(TEXT(J40,"000000000.00"),8,1)<>1,CHOOSE(MID(TEXT(J40,"000000000.00"),9,1)+1,,"One","Two","Three","Four","Five","Six","Seven","Eight","Nine"),CHOOSE(MID(TEXT(J40,"000000000.00"),9,1)+1,"Ten","Eleven","Twelve","Thirteen","Fourteen","Fifteen","Sixteen","Seventeen","Eighteen","Nineteen")) &IF(RIGHT(TEXT(J40,"000000000.00"),2)>"000000000.00"," & "&RIGHT(TEXT(J40,"000000000.00"),2)&" Paise Only.","Only.") -> INR Nineteen Thousand Nine Hundred and Fifty Only.
B43: HSN Code | E43: Taxable Value | F43: Central Tax | H43: State Tax | J43: Total Tax Amount
F44: Rate | G44: Amount | H44: Rate | I44: Amount
B45: =IFERROR(VLOOKUP(F13,InvoiceDetails,18,FALSE)," ") | E45: =IFERROR(VLOOKUP(F13,InvoiceDetails,26,FALSE)," ") -> 19950 | F45: =IFERROR(VLOOKUP(F13,InvoiceDetails,23,FALSE)," ") -> 0.025 | G45: =IFERROR(VLOOKUP(F13,InvoiceDetails,30,FALSE)," ") -> 475 | H45: =IFERROR(VLOOKUP(F13,InvoiceDetails,24,FALSE)," ") -> 0.025 | I45: =IFERROR(VLOOKUP(F13,InvoiceDetails,31,FALSE)," ") -> 475 | J45: =IFERROR(VLOOKUP(F13,InvoiceDetails,33,FALSE)," ") -> 950
B46: Total | E46: =E45 -> 19950 | G46: =G45 -> 475 | I46: =I45 -> 475 | J46: =J45 -> 950
B47: Tax Amount(in words)
B48: INR | C48: ="INR"&CHOOSE(LEFT(TEXT(J46,"000000000.00"))+1,,"One","Two","Three","Four","Five","Six","Seven","Eight","Nine") &IF(--LEFT(TEXT(J46,"000000000.00"))=0,,IF(AND(--MID(TEXT(J46,"000000000.00"),2,1)=0,--MID(TEXT(J46,"000000000.00"),3,1)=0)," Hundred"," Hundred and ")) &CHOOSE(MID(TEXT(J46,"000000000.00"),2,1)+1,,,"Twenty ","Thirty ","Forty ","Fifty ","Sixty ","Seventy ","Eighty ","Ninety ") &IF(--MID(TEXT(J46,"000000000.00"),2,1)<>1,CHOOSE(MID(TEXT(J46,"000000000.00"),3,1)+1,,"One","Two","Three","Four","Five","Six","Seven","Eight","Nine"), CHOOSE(MID(TEXT(J46,"000000000.00"),3,1)+1,"Ten","Eleven","Twelve","Thirteen","Fourteen","Fifteen","Sixteen","Seventeen","Eighteen","Nineteen")) &IF((--LEFT(TEXT(J46,"000000000.00"))+MID(TEXT(J46,"000000000.00"),2,1)+MID(TEXT(J46,"000000000.00"),3,1))=0,,IF(AND((--MID(TEXT(J46,"000000000.00"),4,1)+MID(TEXT(J46,"000000000.00"),5,1)+MID(TEXT(J46,"000000000.00"),6,1)+MID(TEXT(J46,"000000000.00"),7,1))=0,(--MID(TEXT(J46,"000000000.00"),8,1)+RIGHT(TEXT(J46,"000000000.00")))>0)," Million and "," Million ")) &CHOOSE(MID(TEXT(J46,"000000000.00"),4,1)+1,,"One","Two","Three","Four","Five","Six","Seven","Eight","Nine") &IF(--MID(TEXT(J46,"000000000.00"),4,1)=0,,IF(AND(--MID(TEXT(J46,"000000000.00"),5,1)=0,--MID(TEXT(J46,"000000000.00"),6,1)=0)," Hundred"," Hundred and")) &CHOOSE(MID(TEXT(J46,"000000000.00"),5,1)+1,,," Twenty"," Thirty"," Forty"," Fifty"," Sixty"," Seventy"," Eighty"," Ninety") &IF(--MID(TEXT(J46,"000000000.00"),5,1)<>1,CHOOSE(MID(TEXT(J46,"000000000.00"),6,1)+1,," One"," Two"," Three"," Four"," Five"," Six"," Seven"," Eight"," Nine"),CHOOSE(MID(TEXT(J46,"000000000.00"),6,1)+1," Ten"," Eleven"," Twelve"," Thirteen"," Fourteen"," Fifteen"," Sixteen"," Seventeen"," Eighteen"," Nineteen")) &IF((--MID(TEXT(J46,"000000000.00"),4,1)+MID(TEXT(J46,"000000000.00"),5,1)+MID(TEXT(J46,"000000000.00"),6,1))=0,,IF(OR((--MID(TEXT(J46,"000000000.00"),7,1)+MID(TEXT(J46,"000000000.00"),8,1)+MID(TEXT(J46,"000000000.00"),9,1))=0,--MID(TEXT(J46,"000000000.00"),7,1)<>0)," Thousand "," Thousand and ")) &CHOOSE(MID(TEXT(J46,"000000000.00"),7,1)+1,,"One","Two","Three","Four","Five","Six","Seven","Eight","Nine") &IF(--MID(TEXT(J46,"000000000.00"),7,1)=0,,IF(AND(--MID(TEXT(J46,"000000000.00"),8,1)=0,--MID(TEXT(J46,"000000000.00"),9,1)=0)," Hundred "," Hundred and "))& CHOOSE(MID(TEXT(J46,"000000000.00"),8,1)+1,,,"Twenty ","Thirty ","Forty ","Fifty ","Sixty ","Seventy ","Eighty ","Ninety ") &IF(--MID(TEXT(J46,"000000000.00"),8,1)<>1,CHOOSE(MID(TEXT(J46,"000000000.00"),9,1)+1,,"One","Two","Three","Four","Five","Six","Seven","Eight","Nine"),CHOOSE(MID(TEXT(J46,"000000000.00"),9,1)+1,"Ten","Eleven","Twelve","Thirteen","Fourteen","Fifteen","Sixteen","Seventeen","Eighteen","Nineteen")) &IF(RIGHT(TEXT(J46,"000000000.00"),2)>"000000000.00"," & "&RIGHT(TEXT(J46,"000000000.00"),2)&" Paise Only.","Only.") -> INRNine Hundred and Fifty Only.
B50: Remarks: | F50: BANK NAME | H50: STATE BANK OF INDIA
F51: ACCOUNT NO. | H51: 39935045918
B52: PAN | C52: BOPPP0960N | F52: BRANCH & IFS CODE | H52: UDAY NAGAR SBIN0017637
...

Sheet INVOICE Other than MH
B2: TAX INVOICE
B4: MAHALAXMI AGRO ENERGIES | F4: Invoice No. | I4: Dated
B5: 70 Mahakali Nagar 3, Mhalginagar, | F5: =IFERROR(VLOOKUP(F13,InvoiceDetails,11,FALSE)," ") -> 416 | I5: =VLOOKUP(F13,InvoiceDetails,4,FALSE) -> 46021
B6: Hudkeshwar Ring Road, Nagpur 34 | F6: Delivery Note | I6: Payment Mode/Terms
B7: 8550952303 | F7: =IFERROR(VLOOKUP(F13,InvoiceDetails,5,FALSE)," ") -> - | I7: =IFERROR(VLOOKUP(F13,InvoiceDetails,6,FALSE)," ") -> -
B8: GSTN: | C8: 27BOPPP0960N1Z7 | F8: Supplier Ref. | I8: Other Reference(s)
B9: State: | C9: MAHARASHTRA | E9: 440034 | F9: =IFERROR(VLOOKUP(F13,InvoiceDetails,7,FALSE)," ") -> DM- 283 | I9: =IFERROR(VLOOKUP(F13,InvoiceDetails,8,FALSE)," ") -> -
B10: Mail: | C10: biomassenergies@gmail.com | F10: Buyer's Order No. | I10: Dated
B11: Consignee | F11: =IFERROR(VLOOKUP(F13,InvoiceDetails,9,FALSE)," ") -> - | I11: =IFERROR(VLOOKUP(F13,InvoiceDetails,10,FALSE)," ") -> 46021
B12: =VLOOKUP(F13,InvoiceDetails,2,FALSE) -> EXOTIC HOSPITALITY NAGPUR PVT LTD | F12: Despatch Document No. | I12: Delivery Note Date
B13: ='CUSTOMER DETAILS'!C60 -> TATHASTU PENCH PENCH TIGER RESERVE AWARGHANI TURIA SEONI | F13: MAE058/25-26-0018 | I13: =IFERROR(VLOOKUP(F13,InvoiceDetails,12,FALSE)," ") -> -
F14: Despatched Through | I14: Destination
B15: GSTN: | C15: ='CUSTOMER DETAILS'!D60 -> 23AAACE8761B1Z0 | F15: =IFERROR(VLOOKUP(F13,InvoiceDetails,13,FALSE)," ") -> SELF PICKUP | I15: =IFERROR(VLOOKUP(F13,InvoiceDetails,14,FALSE)," ") -> SOENI M.P
B16: State: | C16: ='CUSTOMER DETAILS'!E60 -> MADHYA PRADESH
B17: Mail: | C17: ='CUSTOMER DETAILS'!G60 -> ravi@sandeepdwellers.com | F17: Bill of Landing/LR-RR No. | I17: Motor Vehicle Number
F18: =IFERROR(VLOOKUP(F13,InvoiceDetails,15,FALSE)," ") -> - | I18: =IFERROR(VLOOKUP(F13,InvoiceDetails,16,FALSE)," ") -> MH-49BZ-1179
B20: Buyer (If Other Than Consignee) | F20: Terms Of Delivery
B21: =VLOOKUP(F13,InvoiceDetails,2,FALSE) -> EXOTIC HOSPITALITY NAGPUR PVT LTD
B22: =B13 -> TATHASTU PENCH PENCH TIGER RESERVE AWARGHANI TURIA SEONI
B24: GSTN: | C24: =C15 -> 23AAACE8761B1Z0
B25: State: | C25: =C16 -> MADHYA PRADESH
B26: Mail: | C26: =C17 -> ravi@sandeepdwellers.com
B27: Sr. No. | C27: Description Of Goods | F27: HSN Code | G27: Quatity | H27: Rate | I27: Per | J27: Amount
B28: 1 | C28: =IFERROR(VLOOKUP(F13,InvoiceDetails,17,FALSE)," ") -> BIOMASS BRIQUETTE 90MM | G28: =IFERROR(VLOOKUP(F13,InvoiceDetails,19,FALSE)," ") -> 2120 | H28: =IFERROR(VLOOKUP(F13,InvoiceDetails,20,FALSE)," ") -> 8.15 | I28: =IFERROR(VLOOKUP(F13,InvoiceDetails,21,FALSE)," ") -> KG | J28: =IFERROR(VLOOKUP(F13,InvoiceDetails,22,FALSE)," ") -> 17278
E30: IGST OUTPUT @ 5% | H30: =IFERROR(VLOOKUP(F13,InvoiceDetails,25,FALSE)," ") -> 0.05 | J30: =IFERROR(VLOOKUP(F13,InvoiceDetails,32,FALSE)," ") -> 863.9
E32: ROUNDOFF | J32: =IFERROR(VLOOKUP(F13,InvoiceDetails,27,FALSE)," ") -> 0.1
E34: TRANSPORT/UNLOADING | J34: =IFERROR(VLOOKUP(F13,InvoiceDetails,28,FALSE)," ")
E39: Total | G39: =SUM(G28:G38) -> 2120 | J39: =IFERROR(VLOOKUP(F13,InvoiceDetails,26,FALSE)," ") -> 18142
B40: Amount Chargeable(in words) | J40: E. & O.E
B41: INR | C41: ="INR"&CHOOSE(LEFT(TEXT(J39,"000000000.00"))+1,,"One","Two","Three","Four","Five","Six","Seven","Eight","Nine") &IF(--LEFT(TEXT(J39,"000000000.00"))=0,,IF(AND(--MID(TEXT(J39,"000000000.00"),2,1)=0,--MID(TEXT(J39,"000000000.00"),3,1)=0)," Hundred"," Hundred and ")) &CHOOSE(MID(TEXT(J39,"000000000.00"),2,1)+1,,,"Twenty ","Thirty ","Forty ","Fifty ","Sixty ","Seventy ","Eighty ","Ninety ") &IF(--MID(TEXT(J39,"000000000.00"),2,1)<>1,CHOOSE(MID(TEXT(J39,"000000000.00"),3,1)+1,,"One","Two","Three","Four","Five","Six","Seven","Eight","Nine"), CHOOSE(MID(TEXT(J39,"000000000.00"),3,1)+1,"Ten","Eleven","Twelve","Thirteen","Fourteen","Fifteen","Sixteen","Seventeen","Eighteen","Nineteen")) &IF((--LEFT(TEXT(J39,"000000000.00"))+MID(TEXT(J39,"000000000.00"),2,1)+MID(TEXT(J39,"000000000.00"),3,1))=0,,IF(AND((--MID(TEXT(J39,"000000000.00"),4,1)+MID(TEXT(J39,"000000000.00"),5,1)+MID(TEXT(J39,"000000000.00"),6,1)+MID(TEXT(J39,"000000000.00"),7,1))=0,(--MID(TEXT(J39,"000000000.00"),8,1)+RIGHT(TEXT(J39,"000000000.00")))>0)," Million and "," Million ")) &CHOOSE(MID(TEXT(J39,"000000000.00"),4,1)+1,,"One","Two","Three","Four","Five","Six","Seven","Eight","Nine") &IF(--MID(TEXT(J39,"000000000.00"),4,1)=0,,IF(AND(--MID(TEXT(J39,"000000000.00"),5,1)=0,--MID(TEXT(J39,"000000000.00"),6,1)=0)," Hundred"," Hundred and")) &CHOOSE(MID(TEXT(J39,"000000000.00"),5,1)+1,,," Twenty"," Thirty"," Forty"," Fifty"," Sixty"," Seventy"," Eighty"," Ninety") &IF(--MID(TEXT(J39,"000000000.00"),5,1)<>1,CHOOSE(MID(TEXT(J39,"000000000.00"),6,1)+1,," One"," Two"," Three"," Four"," Five"," Six"," Seven"," Eight"," Nine"),CHOOSE(MID(TEXT(J39,"000000000.00"),6,1)+1," Ten"," Eleven"," Twelve"," Thirteen"," Fourteen"," Fifteen"," Sixteen"," Seventeen"," Eighteen"," Nineteen")) &IF((--MID(TEXT(J39,"000000000.00"),4,1)+MID(TEXT(J39,"000000000.00"),5,1)+MID(TEXT(J39,"000000000.00"),6,1))=0,,IF(OR((--MID(TEXT(J39,"000000000.00"),7,1)+MID(TEXT(J39,"000000000.00"),8,1)+MID(TEXT(J39,"000000000.00"),9,1))=0,--MID(TEXT(J39,"000000000.00"),7,1)<>0)," Thousand "," Thousand and ")) &CHOOSE(MID(TEXT(J39,"000000000.00"),7,1)+1,,"One","Two","Three","Four","Five","Six","Seven","Eight","Nine") &IF(--MID(TEXT(J39,"000000000.00"),7,1)=0,,IF(AND(--MID(TEXT(J39,"000000000.00"),8,1)=0,--MID(TEXT(J39,"000000000.00"),9,1)=0)," Hundred "," Hundred and "))& CHOOSE(MID(TEXT(J39,"000000000.00"),8,1)+1,,,"Twenty ","Thirty ","Forty ","Fifty ","Sixty ","Seventy ","Eighty ","Ninety ") &IF(--MID(TEXT(J39,"000000000.00"),8,1)<>1,CHOOSE(MID(TEXT(J39,"000000000.00"),9,1)+1,,"One","Two","Three","Four","Five","Six","Seven","Eight","Nine"),CHOOSE(MID(TEXT(J39,"000000000.00"),9,1)+1,"Ten","Eleven","Twelve","Thirteen","Fourteen","Fifteen","Sixteen","Seventeen","Eighteen","Nineteen")) &IF(RIGHT(TEXT(J39,"000000000.00"),2)>"000000000.00"," & "&RIGHT(TEXT(J39,"000000000.00"),2)&" Paise Only.","Only.") -> INR Eighteen Thousand One Hundred and Forty TwoOnly.
B42: HSN Code | E42: Taxable Value | F42: Central Tax | H42: State Tax | J42: Total Tax Amount
F43: Rate | G43: Amount | H43: Rate | I43: Amount
B44: =IFERROR(VLOOKUP(F13,InvoiceDetails,18,FALSE)," ") -> 44011090 | E44: =IFERROR(VLOOKUP(F13,InvoiceDetails,26,FALSE)," ") -> 18142 | F44: =IFERROR(VLOOKUP(F13,InvoiceDetails,25,FALSE)," ") -> 0.05 | G44: =IFERROR(VLOOKUP(F13,InvoiceDetails,32,FALSE)," ") -> 863.9 | H44: 0 | I44: 0 | J44: =IFERROR(VLOOKUP(F13,InvoiceDetails,32,FALSE)," ") -> 863.9
B45: Total | E45: =E44 -> 18142 | G45: =G44 -> 863.9 | I45: =I44 -> 0 | J45: =J44 -> 863.9
B46: Tax Amount(in words)
B47: INR | C47: ="INR"&CHOOSE(LEFT(TEXT(J45,"000000000.00"))+1,,"One","Two","Three","Four","Five","Six","Seven","Eight","Nine") &IF(--LEFT(TEXT(J45,"000000000.00"))=0,,IF(AND(--MID(TEXT(J45,"000000000.00"),2,1)=0,--MID(TEXT(J45,"000000000.00"),3,1)=0)," Hundred"," Hundred and ")) &CHOOSE(MID(TEXT(J45,"000000000.00"),2,1)+1,,,"Twenty ","Thirty ","Forty ","Fifty ","Sixty ","Seventy ","Eighty ","Ninety ") &IF(--MID(TEXT(J45,"000000000.00"),2,1)<>1,CHOOSE(MID(TEXT(J45,"000000000.00"),3,1)+1,,"One","Two","Three","Four","Five","Six","Seven","Eight","Nine"), CHOOSE(MID(TEXT(J45,"000000000.00"),3,1)+1,"Ten","Eleven","Twelve","Thirteen","Fourteen","Fifteen","Sixteen","Seventeen","Eighteen","Nineteen")) &IF((--LEFT(TEXT(J45,"000000000.00"))+MID(TEXT(J45,"000000000.00"),2,1)+MID(TEXT(J45,"000000000.00"),3,1))=0,,IF(AND((--MID(TEXT(J45,"000000000.00"),4,1)+MID(TEXT(J45,"000000000.00"),5,1)+MID(TEXT(J45,"000000000.00"),6,1)+MID(TEXT(J45,"000000000.00"),7,1))=0,(--MID(TEXT(J45,"000000000.00"),8,1)+RIGHT(TEXT(J45,"000000000.00")))>0)," Million and "," Million ")) &CHOOSE(MID(TEXT(J45,"000000000.00"),4,1)+1,,"One","Two","Three","Four","Five","Six","Seven","Eight","Nine") &IF(--MID(TEXT(J45,"000000000.00"),4,1)=0,,IF(AND(--MID(TEXT(J45,"000000000.00"),5,1)=0,--MID(TEXT(J45,"000000000.00"),6,1)=0)," Hundred"," Hundred and")) &CHOOSE(MID(TEXT(J45,"000000000.00"),5,1)+1,,," Twenty"," Thirty"," Forty"," Fifty"," Sixty"," Seventy"," Eighty"," Ninety") &IF(--MID(TEXT(J45,"000000000.00"),5,1)<>1,CHOOSE(MID(TEXT(J45,"000000000.00"),6,1)+1,," One"," Two"," Three"," Four"," Five"," Six"," Seven"," Eight"," Nine"),CHOOSE(MID(TEXT(J45,"000000000.00"),6,1)+1," Ten"," Eleven"," Twelve"," Thirteen"," Fourteen"," Fifteen"," Sixteen"," Seventeen"," Eighteen"," Nineteen")) &IF((--MID(TEXT(J45,"000000000.00"),4,1)+MID(TEXT(J45,"000000000.00"),5,1)+MID(TEXT(J45,"000000000.00"),6,1))=0,,IF(OR((--MID(TEXT(J45,"000000000.00"),7,1)+MID(TEXT(J45,"000000000.00"),8,1)+MID(TEXT(J45,"000000000.00"),9,1))=0,--MID(TEXT(J45,"000000000.00"),7,1)<>0)," Thousand "," Thousand and ")) &CHOOSE(MID(TEXT(J45,"000000000.00"),7,1)+1,,"One","Two","Three","Four","Five","Six","Seven","Eight","Nine") &IF(--MID(TEXT(J45,"000000000.00"),7,1)=0,,IF(AND(--MID(TEXT(J45,"000000000.00"),8,1)=0,--MID(TEXT(J45,"000000000.00"),9,1)=0)," Hundred "," Hundred and "))& CHOOSE(MID(TEXT(J45,"000000000.00"),8,1)+1,,,"Twenty ","Thirty ","Forty ","Fifty ","Sixty ","Seventy ","Eighty ","Ninety ") &IF(--MID(TEXT(J45,"000000000.00"),8,1)<>1,CHOOSE(MID(TEXT(J45,"000000000.00"),9,1)+1,,"One","Two","Three","Four","Five","Six","Seven","Eight","Nine"),CHOOSE(MID(TEXT(J45,"000000000.00"),9,1)+1,"Ten","Eleven","Twelve","Thirteen","Fourteen","Fifteen","Sixteen","Seventeen","Eighteen","Nineteen")) &IF(RIGHT(TEXT(J45,"000000000.00"),2)>"000000000.00"," & "&RIGHT(TEXT(J45,"000000000.00"),2)&" Paise Only.","Only.") -> INREight Hundred and Sixty Three & 90 Paise Only.
B49: Remarks: | F49: BANK NAME | H49: STATE BANK OF INDIA
F50: ACCT NO. | H50: 39935045918
B51: PAN | C51: BOPPP0960N | F51: BRANCH & IFS CODE | H51: UDAY NAGAR SBIN0017637
B52: Declaration
...

Sheet CREDIT NOTE
B2: PURCHASE ORDER
B4: MAHALAXMI AGRO ENERGIES | F4: Invoice No. | I4: Dated
B5: 70 Mahakali Nagar 3, Mhalginagar, | F5: =IFERROR(VLOOKUP(F13,InvoiceDetails,11,FALSE)," ") | I5: =VLOOKUP(F13,InvoiceDetails,4,FALSE) -> 45757
B6: Hudkeshwar Ring Road, Nagpur 34 | F6: Delivery Note | I6: Payment Mode/Terms
B7: 8550952303 | F7: =IFERROR(VLOOKUP(F13,InvoiceDetails,5,FALSE)," ") -> - | I7: =IFERROR(VLOOKUP(F13,InvoiceDetails,6,FALSE)," ") -> -
B8: GSTN: | C8: 27BOPPP0960N1Z7 | F8: Supplier Ref. | I8: Other Reference(s)
B9: State: | C9: MAHARASHTRA | E9: 440034 | F9: =IFERROR(VLOOKUP(F13,InvoiceDetails,7,FALSE)," ") -> - | I9: =IFERROR(VLOOKUP(F13,InvoiceDetails,8,FALSE)," ") -> PO NO 25-26/001
B10: Mail: | C10: biomassenergies@gmail.com | F10: Buyer's Order No. | I10: Dated
B11: Consignee | F11: =IFERROR(VLOOKUP(F13,InvoiceDetails,9,FALSE)," ") -> - | I11: =IFERROR(VLOOKUP(F13,InvoiceDetails,10,FALSE)," ") -> 45757
B12: =VLOOKUP(F13,InvoiceDetails,2,FALSE) -> Sankalp Industries | F12: Despatch Document No. | I12: Delivery Note Date
B13: =VLOOKUP(B12,CustDetail1,2,FALSE) -> Nimbhora Lahe, Badnera Amravati | F13: MAE053 | I13: =IFERROR(VLOOKUP(F13,InvoiceDetails,12,FALSE)," ") -> -
F14: Despatched Through | I14: Destination
B15: GSTN: | C15: =VLOOKUP(B12,CustDetail1,3,FALSE) -> 27ACLFS7336L1ZF | F15: =IFERROR(VLOOKUP(F13,InvoiceDetails,13,FALSE)," ") | I15: =IFERROR(VLOOKUP(F13,InvoiceDetails,14,FALSE)," ")
B16: State: | C16: =VLOOKUP(B12,CustDetail1,4,FALSE) -> MAHARASHTRA | E16: =VLOOKUP(B12,CustDetail1,5,FALSE) -> 444601
B17: Mail: | C17: =VLOOKUP(B12,CustDetail1,6,FALSE) | F17: Bill of Landing/LR-RR No. | I17: Motor Vehicle Number
F18: =IFERROR(VLOOKUP(F13,InvoiceDetails,15,FALSE)," ") -> - | I18: =IFERROR(VLOOKUP(F13,InvoiceDetails,16,FALSE)," ")
B20: Buyer (If Other Than Consignee)
B21: =VLOOKUP(F13,InvoiceDetails,2,FALSE) -> Sankalp Industries
B22: =VLOOKUP(B21,CustDetail1,2,FALSE) -> Nimbhora Lahe, Badnera Amravati
B24: GSTN: | C24: =VLOOKUP(B12,CustDetail1,3,FALSE) -> 27ACLFS7336L1ZF
B25: State: | C25: =VLOOKUP(B12,CustDetail1,4,FALSE) -> MAHARASHTRA | E25: =VLOOKUP(B12,CustDetail1,5,FALSE) -> 444601
B26: Mail: | C26: =VLOOKUP(B12,CustDetail1,6,FALSE)
B27: Sr. No. | C27: Description Of Goods | F27: HSN Code | G27: Quatity | H27: Rate | I27: Per | J27: Amount
B28: 1 | C28: =IFERROR(VLOOKUP(F13,InvoiceDetails,17,FALSE)," ") -> BIOMASS BRIQUETTE 90MM | F28: =IFERROR(VLOOKUP(F13,InvoiceDetails,18,FALSE)," ") -> 44011090 | G28: =IFERROR(VLOOKUP(F13,InvoiceDetails,19,FALSE)," ") -> 50000 | H28: =IFERROR(VLOOKUP(F13,InvoiceDetails,20,FALSE)," ") -> 6.1 | I28: =IFERROR(VLOOKUP(F13,InvoiceDetails,21,FALSE)," ") -> KG | J28: =IFERROR(VLOOKUP(F13,InvoiceDetails,22,FALSE)," ") -> 305000
E30: IGST OUTPUT @ 5% | H30: =IFERROR(VLOOKUP(F13,InvoiceDetails,25,FALSE)," ") | J30: =IFERROR(VLOOKUP(F13,InvoiceDetails,32,FALSE)," ") -> 0
E32: ROUNDOFF | J32: =IFERROR(VLOOKUP(F13,InvoiceDetails,27,FALSE)," ") -> 0
E34: TRANSPORT/UNLOADING | J34: =IFERROR(VLOOKUP(F13,InvoiceDetails,28,FALSE)," ")
E39: Total | G39: =SUM(G28:G38) -> 50000 | J39: =IFERROR(VLOOKUP(F13,InvoiceDetails,26,FALSE)," ") -> 320250
B40: Amount Chargeable(in words) | J40: E. & O.E
B41: INR | C41: ="INR"&CHOOSE(LEFT(TEXT(J39,"000000000.00"))+1,,"One","Two","Three","Four","Five","Six","Seven","Eight","Nine") &IF(--LEFT(TEXT(J39,"000000000.00"))=0,,IF(AND(--MID(TEXT(J39,"000000000.00"),2,1)=0,--MID(TEXT(J39,"000000000.00"),3,1)=0)," Hundred"," Hundred and ")) &CHOOSE(MID(TEXT(J39,"000000000.00"),2,1)+1,,,"Twenty ","Thirty ","Forty ","Fifty ","Sixty ","Seventy ","Eighty ","Ninety ") &IF(--MID(TEXT(J39,"000000000.00"),2,1)<>1,CHOOSE(MID(TEXT(J39,"000000000.00"),3,1)+1,,"One","Two","Three","Four","Five","Six","Seven","Eight","Nine"), CHOOSE(MID(TEXT(J39,"000000000.00"),3,1)+1,"Ten","Eleven","Twelve","Thirteen","Fourteen","Fifteen","Sixteen","Seventeen","Eighteen","Nineteen")) &IF((--LEFT(TEXT(J39,"000000000.00"))+MID(TEXT(J39,"000000000.00"),2,1)+MID(TEXT(J39,"000000000.00"),3,1))=0,,IF(AND((--MID(TEXT(J39,"000000000.00"),4,1)+MID(TEXT(J39,"000000000.00"),5,1)+MID(TEXT(J39,"000000000.00"),6,1)+MID(TEXT(J39,"000000000.00"),7,1))=0,(--MID(TEXT(J39,"000000000.00"),8,1)+RIGHT(TEXT(J39,"000000000.00")))>0)," Million and "," Million ")) &CHOOSE(MID(TEXT(J39,"000000000.00"),4,1)+1,,"One","Two","Three","Four","Five","Six","Seven","Eight","Nine") &IF(--MID(TEXT(J39,"000000000.00"),4,1)=0,,IF(AND(--MID(TEXT(J39,"000000000.00"),5,1)=0,--MID(TEXT(J39,"000000000.00"),6,1)=0)," Hundred"," Hundred and")) &CHOOSE(MID(TEXT(J39,"000000000.00"),5,1)+1,,," Twenty"," Thirty"," Forty"," Fifty"," Sixty"," Seventy"," Eighty"," Ninety") &IF(--MID(TEXT(J39,"000000000.00"),5,1)<>1,CHOOSE(MID(TEXT(J39,"000000000.00"),6,1)+1,," One"," Two"," Three"," Four"," Five"," Six"," Seven"," Eight"," Nine"),CHOOSE(MID(TEXT(J39,"000000000.00"),6,1)+1," Ten"," Eleven"," Twelve"," Thirteen"," Fourteen"," Fifteen"," Sixteen"," Seventeen"," Eighteen"," Nineteen")) &IF((--MID(TEXT(J39,"000000000.00"),4,1)+MID(TEXT(J39,"000000000.00"),5,1)+MID(TEXT(J39,"000000000.00"),6,1))=0,,IF(OR((--MID(TEXT(J39,"000000000.00"),7,1)+MID(TEXT(J39,"000000000.00"),8,1)+MID(TEXT(J39,"000000000.00"),9,1))=0,--MID(TEXT(J39,"000000000.00"),7,1)<>0)," Thousand "," Thousand and ")) &CHOOSE(MID(TEXT(J39,"000000000.00"),7,1)+1,,"One","Two","Three","Four","Five","Six","Seven","Eight","Nine") &IF(--MID(TEXT(J39,"000000000.00"),7,1)=0,,IF(AND(--MID(TEXT(J39,"000000000.00"),8,1)=0,--MID(TEXT(J39,"000000000.00"),9,1)=0)," Hundred "," Hundred and "))& CHOOSE(MID(TEXT(J39,"000000000.00"),8,1)+1,,,"Twenty ","Thirty ","Forty ","Fifty ","Sixty ","Seventy ","Eighty ","Ninety ") &IF(--MID(TEXT(J39,"000000000.00"),8,1)<>1,CHOOSE(MID(TEXT(J39,"000000000.00"),9,1)+1,,"One","Two","Three","Four","Five","Six","Seven","Eight","Nine"),CHOOSE(MID(TEXT(J39,"000000000.00"),9,1)+1,"Ten","Eleven","Twelve","Thirteen","Fourteen","Fifteen","Sixteen","Seventeen","Eighteen","Nineteen")) &IF(RIGHT(TEXT(J39,"000000000.00"),2)>"000000000.00"," & "&RIGHT(TEXT(J39,"000000000.00"),2)&" Paise Only.","Only.") -> INRThree Hundred and Twenty Thousand Two Hundred and Fifty Only.
B42: HSN Code | E42: Taxable Value | F42: Central Tax | H42: State Tax | J42: Total Tax Amount
F43: Rate | G43: Amount | H43: Rate | I43: Amount
B44: =IFERROR(VLOOKUP(F13,InvoiceDetails,18,FALSE)," ") -> 44011090 | E44: =IFERROR(VLOOKUP(F13,InvoiceDetails,26,FALSE)," ") -> 320250 | F44: =IFERROR(VLOOKUP(F13,InvoiceDetails,25,FALSE)," ") | G44: =IFERROR(VLOOKUP(F13,InvoiceDetails,32,FALSE)," ") -> 0 | H44: 0 | I44: 0 | J44: =IFERROR(VLOOKUP(F13,InvoiceDetails,32,FALSE)," ") -> 0
B45: Total | E45: =E44 -> 320250 | G45: =G44 -> 0 | I45: =I44 -> 0 | J45: =J44 -> 0
B46: Tax Amount(in words)
B47: INR | C47: ="INR"&CHOOSE(LEFT(TEXT(J45,"000000000.00"))+1,,"One","Two","Three","Four","Five","Six","Seven","Eight","Nine") &IF(--LEFT(TEXT(J45,"000000000.00"))=0,,IF(AND(--MID(TEXT(J45,"000000000.00"),2,1)=0,--MID(TEXT(J45,"000000000.00"),3,1)=0)," Hundred"," Hundred and ")) &CHOOSE(MID(TEXT(J45,"000000000.00"),2,1)+1,,,"Twenty ","Thirty ","Forty ","Fifty ","Sixty ","Seventy ","Eighty ","Ninety ") &IF(--MID(TEXT(J45,"000000000.00"),2,1)<>1,CHOOSE(MID(TEXT(J45,"000000000.00"),3,1)+1,,"One","Two","Three","Four","Five","Six","Seven","Eight","Nine"), CHOOSE(MID(TEXT(J45,"000000000.00"),3,1)+1,"Ten","Eleven","Twelve","Thirteen","Fourteen","Fifteen","Sixteen","Seventeen","Eighteen","Nineteen")) &IF((--LEFT(TEXT(J45,"000000000.00"))+MID(TEXT(J45,"000000000.00"),2,1)+MID(TEXT(J45,"000000000.00"),3,1))=0,,IF(AND((--MID(TEXT(J45,"000000000.00"),4,1)+MID(TEXT(J45,"000000000.00"),5,1)+MID(TEXT(J45,"000000000.00"),6,1)+MID(TEXT(J45,"000000000.00"),7,1))=0,(--MID(TEXT(J45,"000000000.00"),8,1)+RIGHT(TEXT(J45,"000000000.00")))>0)," Million and "," Million ")) &CHOOSE(MID(TEXT(J45,"000000000.00"),4,1)+1,,"One","Two","Three","Four","Five","Six","Seven","Eight","Nine") &IF(--MID(TEXT(J45,"000000000.00"),4,1)=0,,IF(AND(--MID(TEXT(J45,"000000000.00"),5,1)=0,--MID(TEXT(J45,"000000000.00"),6,1)=0)," Hundred"," Hundred and")) &CHOOSE(MID(TEXT(J45,"000000000.00"),5,1)+1,,," Twenty"," Thirty"," Forty"," Fifty"," Sixty"," Seventy"," Eighty"," Ninety") &IF(--MID(TEXT(J45,"000000000.00"),5,1)<>1,CHOOSE(MID(TEXT(J45,"000000000.00"),6,1)+1,," One"," Two"," Three"," Four"," Five"," Six"," Seven"," Eight"," Nine"),CHOOSE(MID(TEXT(J45,"000000000.00"),6,1)+1," Ten"," Eleven"," Twelve"," Thirteen"," Fourteen"," Fifteen"," Sixteen"," Seventeen"," Eighteen"," Nineteen")) &IF((--MID(TEXT(J45,"000000000.00"),4,1)+MID(TEXT(J45,"000000000.00"),5,1)+MID(TEXT(J45,"000000000.00"),6,1))=0,,IF(OR((--MID(TEXT(J45,"000000000.00"),7,1)+MID(TEXT(J45,"000000000.00"),8,1)+MID(TEXT(J45,"000000000.00"),9,1))=0,--MID(TEXT(J45,"000000000.00"),7,1)<>0)," Thousand "," Thousand and ")) &CHOOSE(MID(TEXT(J45,"000000000.00"),7,1)+1,,"One","Two","Three","Four","Five","Six","Seven","Eight","Nine") &IF(--MID(TEXT(J45,"000000000.00"),7,1)=0,,IF(AND(--MID(TEXT(J45,"000000000.00"),8,1)=0,--MID(TEXT(J45,"000000000.00"),9,1)=0)," Hundred "," Hundred and "))& CHOOSE(MID(TEXT(J45,"000000000.00"),8,1)+1,,,"Twenty ","Thirty ","Forty ","Fifty ","Sixty ","Seventy ","Eighty ","Ninety ") &IF(--MID(TEXT(J45,"000000000.00"),8,1)<>1,CHOOSE(MID(TEXT(J45,"000000000.00"),9,1)+1,,"One","Two","Three","Four","Five","Six","Seven","Eight","Nine"),CHOOSE(MID(TEXT(J45,"000000000.00"),9,1)+1,"Ten","Eleven","Twelve","Thirteen","Fourteen","Fifteen","Sixteen","Seventeen","Eighteen","Nineteen")) &IF(RIGHT(TEXT(J45,"000000000.00"),2)>"000000000.00"," & "&RIGHT(TEXT(J45,"000000000.00"),2)&" Paise Only.","Only.") -> INROnly.
B49: Remarks: | F49: BANK NAME | H49: STATE BANK OF INDIA
F50: ACCT NO. | H50: 39935045918
B51: PAN | C51: BOPPP0960N | F51: BRANCH & IFS CODE | H51: UDAY NAGAR SBIN0017637
B52: Declaration
...

Sheet INVOICE DETAILS
A1: Invoice Number | B1: Consignee Name | C1: Buyer | D1: Dated | E1: Delivery Note | F1: Payment Mode/Terms | G1: Supplier Ref. | H1: Other Reference(s) | I1: Buyer's Order No. | J1: Date | K1: Despatch Document No. | L1: Delivery Note Date | M1: Despatch through | N1: Destination | O1: Bill of Landing/LR-RR No. | P1: Motor Vehicle Number | Q1: Description of Goods | R1: HSN Code | S1: QTY | T1: Rate | U1: per(wt) | V1: Amount | W1: SGST | X1: CGST | Y1: IGST | Z1: Total | AA1: Roundoff | AB1: Transport | AC1: Taxable Value | AD1: SGST AMT | AE1: CGST AMT | AF1: IGST | AG1: Tax Total | AH1: Month | AI1: Year
A2: MAE001/2021-24 | B2: =VLOOKUP((LEFT(A2,6)),CUSTOMER_DETAILS,2,FALSE) -> JEEVIKA YUGCHEM PVT LTD. | C2: - | D2: 44220 | E2: - | F2: - | G2: - | H2: - | I2: JYC/PO/PM/20-21/231 | J2: 44217 | K2: 1 | L2: - | M2: TRUCK | N2: MIDC Butibori | O2: - | P2: MH40N8211 | Q2: BIOMASS BRIQUETTE 90MM | R2: =VLOOKUP(Q2,'PRODUCT TABLE'!$A$2:$B$26,2,FALSE) -> 44011090 | S2: 10900 | T2: 5.05 | U2: KG | V2: =S2*T2 -> 55045 | W2: 0.025 | X2: 0.025 | Y2: 0 | Z2: =IF(((ROUNDUP((AG2+V2),0))-(AG2+V2))>0.49,ROUNDdown((AG2+V2),0),ROUNDup((AG2+V2),0)) + AB2 -> 57797 | AA2: =Z2-(V2+AG2 + AB2) -> -0.25 | AC2: =V2 -> 55045 | AD2: =AC2*W2 -> 1376.125 | AE2: =AC2*X2 -> 1376.125 | AF2: =AC2*Y2 -> 0 | AG2: =SUM(AD2:AF2) -> 2752.25 | AH2: =IFERROR(MONTH(D2)," ") -> 1 | AI2: =YEAR(D2) -> 2021
A3: MAE001/2021-02 | B3: =VLOOKUP((LEFT(A3,6)),CUSTOMER_DETAILS,2,FALSE) -> JEEVIKA YUGCHEM PVT LTD. | C3: - | D3: 44231 | E3: - | F3: - | G3: - | H3: - | I3: JYC/PO/PM/20-21/236 | J3: 44217 | K3: 2 | L3: - | M3: TRUCK | N3: MIDC Butibori | O3: - | P3: MH40N8725 | Q3: BIOMASS BRIQUETTE 90MM | R3: =VLOOKUP(Q3,'PRODUCT TABLE'!$A$2:$B$26,2,FALSE) -> 44011090 | S3: 9430 | T3: 5.05 | U3: KG | V3: =S3*T3 -> 47621.5 | W3: 0.025 | X3: 0.025 | Y3: 0 | Z3: =IF(((ROUNDUP((AG3+V3),0))-(AG3+V3))>0.49,ROUNDdown((AG3+V3),0),ROUNDup((AG3+V3),0)) + AB3 -> 50003 | AA3: =Z3-(V3+AG3 + AB3) -> 0.425 | AC3: =V3 -> 47621.5 | AD3: =AC3*W3 -> 1190.5375 | AE3: =AC3*X3 -> 1190.5375 | AF3: =AC3*Y3 -> 0 | AG3: =SUM(AD3:AF3) -> 2381.075 | AH3: =IFERROR(MONTH(D3)," ") -> 2 | AI3: =YEAR(D3) -> 2021
A4: MAE001/2021-03 | B4: =VLOOKUP((LEFT(A4,6)),CUSTOMER_DETAILS,2,FALSE) -> JEEVIKA YUGCHEM PVT LTD. | C4: - | D4: 44243 | E4: - | F4: - | G4: - | H4: - | I4: JYC/PO/PM/20-21/236 | J4: 44217 | K4: 3 | L4: - | M4: TRUCK | N4: MIDC Butibori | O4: - | P4: MH40N8500 | Q4: BIOMASS BRIQUETTE 90MM | R4: =VLOOKUP(Q4,'PRODUCT TABLE'!$A$2:$B$26,2,FALSE) -> 44011090 | S4: 9365 | T4: 5.05 | U4: KG | V4: =S4*T4 -> 47293.25 | W4: 0.025 | X4: 0.025 | Y4: 0 | Z4: =IF(((ROUNDUP((AG4+V4),0))-(AG4+V4))>0.49,ROUNDdown((AG4+V4),0),ROUNDup((AG4+V4),0)) + AB4 -> 49658 | AA4: =Z4-(V4+AG4 + AB4) -> 0.0875 | AC4: =V4 -> 47293.25 | AD4: =AC4*W4 -> 1182.3312 | AE4: =AC4*X4 -> 1182.3312 | AF4: =AC4*Y4 -> 0 | AG4: =SUM(AD4:AF4) -> 2364.6625 | AH4: =IFERROR(MONTH(D4)," ") -> 2 | AI4: =YEAR(D4) -> 2021
A5: MAE001/2021-04 | B5: =VLOOKUP((LEFT(A5,6)),CUSTOMER_DETAILS,2,FALSE) -> JEEVIKA YUGCHEM PVT LTD. | C5: - | D5: 44253 | E5: - | F5: - | G5: - | H5: - | I5: JYC/PO/PM/20-21/236 | J5: 44253 | K5: 4 | L5: - | M5: TRUCK | N5: MIDC Butibori | O5: - | P5: MH14BT0796 | Q5: BIOMASS BRIQUETTE 90MM | R5: =VLOOKUP(Q5,'PRODUCT TABLE'!$A$2:$B$26,2,FALSE) -> 44011090 | S5: 10030 | T5: 5.05 | U5: KG | V5: =S5*T5 -> 50651.5 | W5: 0.025 | X5: 0.025 | Y5: 0 | Z5: =IF(((ROUNDUP((AG5+V5),0))-(AG5+V5))>0.49,ROUNDdown((AG5+V5),0),ROUNDup((AG5+V5),0)) + AB5 -> 53184 | AA5: =Z5-(V5+AG5 + AB5) -> -0.075 | AC5: =V5 -> 50651.5 | AD5: =AC5*W5 -> 1266.2875 | AE5: =AC5*X5 -> 1266.2875 | AF5: =AC5*Y5 -> 0 | AG5: =SUM(AD5:AF5) -> 2532.575 | AH5: =IFERROR(MONTH(D5)," ") -> 2 | AI5: =YEAR(D5) -> 2021
A6: MAE001/2021-05 | B6: =VLOOKUP((LEFT(A6,6)),CUSTOMER_DETAILS,2,FALSE) -> JEEVIKA YUGCHEM PVT LTD. | C6: - | D6: 44277 | E6: - | F6: - | G6: - | H6: - | I6: JYC/PO/PM/20-21/236 | J6: 44277 | K6: 5 | L6: - | M6: TRUCK | N6: MIDC Butibori | O6: - | P6: MH40N8542 | Q6: BIOMASS BRIQUETTE 90MM | R6: =VLOOKUP(Q6,'PRODUCT TABLE'!$A$2:$B$26,2,FALSE) -> 44011090 | S6: 10640 | T6: 5.05 | U6: KG | V6: =S6*T6 -> 53732 | W6: 0.025 | X6: 0.025 | Y6: 0 | Z6: =IF(((ROUNDUP((AG6+V6),0))-(AG6+V6))>0.49,ROUNDdown((AG6+V6),0),ROUNDup((AG6+V6),0)) + AB6 -> 56419 | AA6: =Z6-(V6+AG6 + AB6) -> 0.4 | AC6: =V6 -> 53732 | AD6: =AC6*W6 -> 1343.3 | AE6: =AC6*X6 -> 1343.3 | AF6: =AC6*Y6 -> 0 | AG6: =SUM(AD6:AF6) -> 2686.6 | AH6: =IFERROR(MONTH(D6)," ") -> 3 | AI6: =YEAR(D6) -> 2021
A7: MAE001/2021-06 | B7: =VLOOKUP((LEFT(A7,6)),CUSTOMER_DETAILS,2,FALSE) -> JEEVIKA YUGCHEM PVT LTD. | C7: - | D7: 44305 | E7: - | F7: - | G7: - | H7: - | I7: JYC/PO/PM/20-21/236 | J7: =D7 -> 44305 | K7: 6 | L7: - | M7: TRUCK | N7: MIDC Butibori | O7: - | P7: MH07C7315 | Q7: BIOMASS BRIQUETTE 90MM | R7: =VLOOKUP(Q7,'PRODUCT TABLE'!$A$2:$B$26,2,FALSE) -> 44011090 | S7: 11120 | T7: 5.05 | U7: KG | V7: =S7*T7 -> 56156 | W7: 0.025 | X7: 0.025 | Y7: 0 | Z7: =IF(((ROUNDUP((AG7+V7),0))-(AG7+V7))>0.49,ROUNDdown((AG7+V7),0),ROUNDup((AG7+V7),0)) + AB7 -> 58964 | AA7: =Z7-(V7+AG7 + AB7) -> 0.2 | AC7: =V7 -> 56156 | AD7: =AC7*W7 -> 1403.9 | AE7: =AC7*X7 -> 1403.9 | AF7: =AC7*Y7 -> 0 | AG7: =SUM(AD7:AF7) -> 2807.8 | AH7: =IFERROR(MONTH(D7)," ") -> 4 | AI7: =YEAR(D7) -> 2021
A8: MAE002/2021-01 | B8: =VLOOKUP((LEFT(A8,6)),CUSTOMER_DETAILS,2,FALSE) -> PDDR MEDICAL PRODUCTS & SERVICES PVT LTD | C8: - | D8: 44317 | E8: - | F8: - | G8: - | H8: - | I8: - | J8: 44317 | K8: 7 | L8: - | M8: TRUCK | N8: Hingana | O8: - | P8: MH40N0129 | Q8: BIOMASS BRIQUETTE 90MM | R8: =VLOOKUP(Q8,'PRODUCT TABLE'!$A$2:$B$26,2,FALSE) -> 44011090 | S8: 10100 | T8: 5.05 | U8: KG | V8: =S8*T8 -> 51005 | W8: 0.025 | X8: 0.025 | Y8: 0 | Z8: =IF(((ROUNDUP((AG8+V8),0))-(AG8+V8))>0.49,ROUNDdown((AG8+V8),0),ROUNDup((AG8+V8),0)) + AB8 -> 53555 | AA8: =Z8-(V8+AG8 + AB8) -> -0.25 | AC8: =V8 -> 51005 | AD8: =AC8*W8 -> 1275.125 | AE8: =AC8*X8 -> 1275.125 | AF8: =AC8*Y8 -> 0 | AG8: =SUM(AD8:AF8) -> 2550.25 | AH8: =IFERROR(MONTH(D8)," ") -> 5 | AI8: =YEAR(D8) -> 2021
A9: MAE002/2021-02 | B9: =VLOOKUP((LEFT(A9,6)),CUSTOMER_DETAILS,2,FALSE) -> PDDR MEDICAL PRODUCTS & SERVICES PVT LTD | C9: - | D9: 44348 | E9: - | F9: - | G9: - | H9: - | I9: - | J9: 44348 | K9: 8 | L9: - | M9: TRUCK | N9: Hingana | O9: - | P9: MH40N6407 | Q9: BIOMASS BRIQUETTE 90MM | R9: =VLOOKUP(Q9,'PRODUCT TABLE'!$A$2:$B$26,2,FALSE) -> 44011090 | S9: 7760 | T9: 5.05 | U9: KG | V9: =S9*T9 -> 39188 | W9: 0.025 | X9: 0.025 | Y9: 0 | Z9: =IF(((ROUNDUP((AG9+V9),0))-(AG9+V9))>0.49,ROUNDdown((AG9+V9),0),ROUNDup((AG9+V9),0)) + AB9 -> 41147 | AA9: =Z9-(V9+AG9 + AB9) -> -0.4 | AC9: =V9 -> 39188 | AD9: =AC9*W9 -> 979.7 | AE9: =AC9*X9 -> 979.7 | AF9: =AC9*Y9 -> 0 | AG9: =SUM(AD9:AF9) -> 1959.4 | AH9: =IFERROR(MONTH(D9)," ") -> 6 | AI9: =YEAR(D9) -> 2021
A10: MAE003/2021-01 | B10: =VLOOKUP((LEFT(A10,6)),CUSTOMER_DETAILS,2,FALSE) -> SHREE GAYATRI PACKAGING | C10: - | D10: 44373 | E10: - | F10: - | G10: - | H10: - | I10: - | J10: 44373 | K10: 9 | L10: - | M10: PVT VHCL | N10: WARDHA | O10: - | P10: MH49AS | Q10: BIOMASS PELLET 06MM | R10: =VLOOKUP(Q10,'PRODUCT TABLE'!$A$2:$B$26,2,FALSE) -> 44011090 | S10: 630 | T10: 10.8 | U10: KG | V10: =S10*T10 -> 6804 | W10: 0.025 | X10: 0.025 | Y10: 0 | Z10: =IF(((ROUNDUP((AG10+V10),0))-(AG10+V10))>0.49,ROUNDdown((AG10+V10),0),ROUNDup((AG10+V10),0)) + AB10 -> 7144 | AA10: =Z10-(V10+AG10 + AB10) -> -0.2 | AC10: =V10 -> 6804 | AD10: =AC10*W10 -> 170.1 | AE10: =AC10*X10 -> 170.1 | AF10: =AC10*Y10 -> 0 | AG10: =SUM(AD10:AF10) -> 340.2 | AH10: =IFERROR(MONTH(D10)," ") -> 6 | AI10: =YEAR(D10) -> 2021
A11: MAE002/2021-03 | B11: =VLOOKUP((LEFT(A11,6)),CUSTOMER_DETAILS,2,FALSE) -> PDDR MEDICAL PRODUCTS & SERVICES PVT LTD | C11: - | D11: 44367 | E11: - | F11: - | G11: - | H11: - | I11: - | J11: 44367 | K11: 10 | L11: - | M11: TRUCK | N11: Hingana | O11: - | Q11: BIOMASS BRIQUETTE 90MM | R11: =VLOOKUP(Q11,'PRODUCT TABLE'!$A$2:$B$26,2,FALSE) -> 44011090 | S11: 7560 | T11: 5.15 | U11: KG | V11: =S11*T11 -> 38934 | W11: 0.025 | X11: 0.025 | Y11: 0 | Z11: =IF(((ROUNDUP((AG11+V11),0))-(AG11+V11))>0.49,ROUNDdown((AG11+V11),0),ROUNDup((AG11+V11),0)) + AB11 -> 40881 | AA11: =Z11-(V11+AG11 + AB11) -> 0.3 | AC11: =V11 -> 38934 | AD11: =AC11*W11 -> 973.35 | AE11: =AC11*X11 -> 973.35 | AF11: =AC11*Y11 -> 0 | AG11: =SUM(AD11:AF11) -> 1946.7 | AH11: =IFERROR(MONTH(D11)," ") -> 6 | AI11: =YEAR(D11) -> 2021
A12: MAE002/2021-04 | B12: =VLOOKUP((LEFT(A12,6)),CUSTOMER_DETAILS,2,FALSE) -> PDDR MEDICAL PRODUCTS & SERVICES PVT LTD | C12: - | D12: 44387 | E12: - | F12: - | G12: - | H12: - | I12: - | J12: 44389 | K12: 11 | L12: - | M12: TRUCK | N12: Hingana | O12: - | P12: MH40L2873 | Q12: BIOMASS BRIQUETTE 90MM | R12: =VLOOKUP(Q12,'PRODUCT TABLE'!$A$2:$B$26,2,FALSE) -> 44011090 | S12: 7420 | T12: 5.5 | U12: KG | V12: =S12*T12 -> 40810 | W12: 0.025 | X12: 0.025 | Y12: 0 | Z12: =IF(((ROUNDUP((AG12+V12),0))-(AG12+V12))>0.49,ROUNDdown((AG12+V12),0),ROUNDup((AG12+V12),0)) + AB12 -> 42850 | AA12: =Z12-(V12+AG12 + AB12) -> -0.5 | AC12: =V12 -> 40810 | AD12: =AC12*W12 -> 1020.25 | AE12: =AC12*X12 -> 1020.25 | AF12: =AC12*Y12 -> 0 | AG12: =SUM(AD12:AF12) -> 2040.5 | AH12: =IFERROR(MONTH(D12)," ") -> 7 | AI12: =YEAR(D12) -> 2021
A13: MAE003 | B13: =iferror(VLOOKUP((LEFT(A13,6)),CUSTOMER_DETAILS,2,FALSE),"-") -> SHREE GAYATRI PACKAGING | C13: - | D13: 44403 | E13: - | F13: - | G13: - | H13: - | I13: - | J13: =D13 -> 44403 | K13: 12 | L13: - | M13: TRUCK | N13: SELDOH NAGPUR | O13: - | Q13: BIOMASS PELLET 06MM | R13: =IFERROR(VLOOKUP(Q13,'PRODUCT TABLE'!$A$2:$B$26,2,FALSE),"-") -> 44011090 | S13: 900 | T13: 10.8 | U13: KG | V13: =S13*T13 -> 9720 | W13: 0.025 | X13: 0.025 | Y13: 0 | Z13: =IF(((ROUNDUP((AG13+V13),0))-(AG13+V13))>0.49,ROUNDdown((AG13+V13),0),ROUNDup((AG13+V13),0)) + AB13 -> 10206 | AA13: =Z13-(V13+AG13 + AB13) -> 0 | AC13: =V13 -> 9720 | AD13: =AC13*W13 -> 243 | AE13: =AC13*X13 -> 243 | AF13: =AC13*Y13 -> 0 | AG13: =SUM(AD13:AF13) -> 486 | AH13: =IFERROR(MONTH(D13)," ") -> 7 | AI13: =YEAR(D13) -> 2021
A14: MAE003 | B14: =iferror(VLOOKUP((LEFT(A14,6)),CUSTOMER_DETAILS,2,FALSE),"-") -> SHREE GAYATRI PACKAGING | C14: - | D14: 44416 | E14: - | F14: - | G14: - | H14: - | I14: - | J14: =D14 -> 44416 | K14: 15 | L14: - | M14: TRUCK | N14: SELDOH NAGPUR | O14: - | Q14: BIOMASS PELLET 06MM | R14: =IFERROR(VLOOKUP(Q14,'PRODUCT TABLE'!$A$2:$B$26,2,FALSE),"-") -> 44011090 | S14: 1000 | T14: 10.8 | U14: KG | V14: =S14*T14 -> 10800 | W14: 0.025 | X14: 0.025 | Y14: 0 | Z14: =IF(((ROUNDUP((AG14+V14),0))-(AG14+V14))>0.49,ROUNDdown((AG14+V14),0),ROUNDup((AG14+V14),0)) + AB14 -> 11340 | AA14: =Z14-(V14+AG14 + AB14) -> 0 | AC14: =V14 -> 10800 | AD14: =AC14*W14 -> 270 | AE14: =AC14*X14 -> 270 | AF14: =AC14*Y14 -> 0 | AG14: =SUM(AD14:AF14) -> 540 | AH14: =IFERROR(MONTH(D14)," ") -> 8 | AI14: =YEAR(D14) -> 2021
A15: MAE003 | B15: =iferror(VLOOKUP((LEFT(A15,6)),CUSTOMER_DETAILS,2,FALSE),"-") -> SHREE GAYATRI PACKAGING | C15: - | D15: 44438 | E15: - | F15: - | G15: - | H15: - | I15: - | J15: =D15 -> 44438 | K15: 16 | L15: - | M15: TRUCK | N15: SELDOH NAGPUR | O15: - | Q15: BIOMASS PELLET 06MM | R15: =IFERROR(VLOOKUP(Q15,'PRODUCT TABLE'!$A$2:$B$26,2,FALSE),"-") -> 44011090 | S15: 1625 | T15: 10.8 | U15: KG | V15: =S15*T15 -> 17550 | W15: 0.025 | X15: 0.025 | Y15: 0 | Z15: =IF(((ROUNDUP((AG15+V15),0))-(AG15+V15))>0.49,ROUNDdown((AG15+V15),0),ROUNDup((AG15+V15),0)) + AB15 -> 18427 | AA15: =Z15-(V15+AG15 + AB15) -> -0.5 | AC15: =V15 -> 17550 | AD15: =AC15*W15 -> 438.75 | AE15: =AC15*X15 -> 438.75 | AF15: =AC15*Y15 -> 0 | AG15: =SUM(AD15:AF15) -> 877.5 | AH15: =IFERROR(MONTH(D15)," ") -> 8 | AI15: =YEAR(D15) -> 2021
A16: MAE003 | B16: =iferror(VLOOKUP((LEFT(A16,6)),CUSTOMER_DETAILS,2,FALSE),"-") -> SHREE GAYATRI PACKAGING | C16: - | D16: 44482 | E16: - | F16: - | G16: - | H16: - | I16: - | J16: =D16 -> 44482 | K16: 17 | L16: - | M16: TRUCK | N16: SELDOH NAGPUR | O16: - | Q16: BIOMASS PELLET 06MM | R16: =IFERROR(VLOOKUP(Q16,'PRODUCT TABLE'!$A$2:$B$26,2,FALSE),"-") -> 44011090 | S16: 1000 | T16: 10.3 | U16: KG | V16: =S16*T16 -> 10300 | W16: 0.025 | X16: 0.025 | Y16: 0 | Z16: =IF(((ROUNDUP((AG16+V16),0))-(AG16+V16))>0.49,ROUNDdown((AG16+V16),0),ROUNDup((AG16+V16),0)) + AB16 -> 10815 | AA16: =Z16-(V16+AG16 + AB16) -> 0 | AC16: =V16 -> 10300 | AD16: =AC16*W16 -> 257.5 | AE16: =AC16*X16 -> 257.5 | AF16: =AC16*Y16 -> 0 | AG16: =SUM(AD16:AF16) -> 515 | AH16: =IFERROR(MONTH(D16)," ") -> 10 | AI16: =YEAR(D16) -> 2021
A17: MAE003 | B17: =iferror(VLOOKUP((LEFT(A17,6)),CUSTOMER_DETAILS,2,FALSE),"-") -> SHREE GAYATRI PACKAGING | C17: - | D17: 44518 | E17: - | F17: - | G17: - | H17: - | I17: - | J17: =D17 -> 44518 | K17: 18 | L17: - | M17: TRUCK | N17: SELDOH NAGPUR | O17: - | Q17: BIOMASS PELLET 06MM | R17: =IFERROR(VLOOKUP(Q17,'PRODUCT TABLE'!$A$2:$B$26,2,FALSE),"-") -> 44011090 | S17: 300 | T17: 10.3 | U17: KG | V17: =S17*T17 -> 3090 | W17: 0.025 | X17: 0.025 | Y17: 0 | Z17: =IF(((ROUNDUP((AG17+V17),0))-(AG17+V17))>0.49,ROUNDdown((AG17+V17),0),ROUNDup((AG17+V17),0)) + AB17 -> 3244 | AA17: =Z17-(V17+AG17 + AB17) -> -0.5 | AC17: =V17 -> 3090 | AD17: =AC17*W17 -> 77.25 | AE17: =AC17*X17 -> 77.25 | AF17: =AC17*Y17 -> 0 | AG17: =SUM(AD17:AF17) -> 154.5 | AH17: =IFERROR(MONTH(D17)," ") -> 11 | AI17: =YEAR(D17) -> 2021
A18: MAE010 | B18: =iferror(VLOOKUP((LEFT(A18,6)),CUSTOMER_DETAILS,2,FALSE),"-") -> KRISHNA ENTERPRISES | C18: - | D18: 44536 | E18: - | F18: - | G18: - | H18: - | I18: - | J18: =D18 -> 44536 | K18: 19 | L18: - | M18: TRUCK | N18: NAGPUR | O18: - | Q18: BIOMASS PELLET 06MM | R18: =IFERROR(VLOOKUP(Q18,'PRODUCT TABLE'!$A$2:$B$26,2,FALSE),"-") -> 44011090 | S18: 1360 | T18: 11 | U18: KG | V18: =S18*T18 -> 14960 | W18: 0.025 | X18: 0.025 | Y18: 0 | Z18: =IF(((ROUNDUP((AG18+V18),0))-(AG18+V18))>0.49,ROUNDdown((AG18+V18),0),ROUNDup((AG18+V18),0)) + AB18 -> 15708 | AA18: =Z18-(V18+AG18 + AB18) -> 0 | AC18: =V18 -> 14960 | AD18: =AC18*W18 -> 374 | AE18: =AC18*X18 -> 374 | AF18: =AC18*Y18 -> 0 | AG18: =SUM(AD18:AF18) -> 748 | AH18: =IFERROR(MONTH(D18)," ") -> 12 | AI18: =YEAR(D18) -> 2021
A19: MAE003 | B19: =iferror(VLOOKUP((LEFT(A19,6)),CUSTOMER_DETAILS,2,FALSE),"-") -> SHREE GAYATRI PACKAGING | C19: - | D19: 44545 | E19: - | F19: - | G19: - | H19: - | I19: - | J19: =D19 -> 44545 | K19: 20 | L19: - | M19: TRUCK | N19: SELDOH NAGPUR | O19: - | Q19: BIOMASS PELLET 06MM | R19: =IFERROR(VLOOKUP(Q19,'PRODUCT TABLE'!$A$2:$B$26,2,FALSE),"-") -> 44011090 | S19: 1115 | T19: 10.5 | U19: KG | V19: =S19*T19 -> 11707.5 | W19: 0.025 | X19: 0.025 | Y19: 0 | Z19: =IF(((ROUNDUP((AG19+V19),0))-(AG19+V19))>0.49,ROUNDdown((AG19+V19),0),ROUNDup((AG19+V19),0)) + AB19 -> 12293 | AA19: =Z19-(V19+AG19 + AB19) -> 0.125 | AC19: =V19 -> 11707.5 | AD19: =AC19*W19 -> 292.6875 | AE19: =AC19*X19 -> 292.6875 | AF19: =AC19*Y19 -> 0 | AG19: =SUM(AD19:AF19) -> 585.375 | AH19: =IFERROR(MONTH(D19)," ") -> 12 | AI19: =YEAR(D19) -> 2021
A20: MAE010 | B20: =iferror(VLOOKUP((LEFT(A20,6)),CUSTOMER_DETAILS,2,FALSE),"-") -> KRISHNA ENTERPRISES | C20: - | D20: 44544 | E20: - | F20: - | G20: - | H20: - | I20: - | J20: =D20 -> 44544 | K20: 21 | L20: - | M20: TRUCK | N20: SELDOH NAGPUR | O20: - | Q20: BIOMASS PELLET 06MM | R20: =IFERROR(VLOOKUP(Q20,'PRODUCT TABLE'!$A$2:$B$26,2,FALSE),"-") -> 44011090 | S20: 2000 | T20: 10.3 | U20: KG | V20: =S20*T20 -> 20600 | W20: 0.025 | X20: 0.025 | Y20: 0 | Z20: =IF(((ROUNDUP((AG20+V20),0))-(AG20+V20))>0.49,ROUNDdown((AG20+V20),0),ROUNDup((AG20+V20),0)) + AB20 -> 21630 | AA20: =Z20-(V20+AG20 + AB20) -> 0 | AC20: =V20 -> 20600 | AD20: =AC20*W20 -> 515 | AE20: =AC20*X20 -> 515 | AF20: =AC20*Y20 -> 0 | AG20: =SUM(AD20:AF20) -> 1030 | AH20: =IFERROR(MONTH(D20)," ") -> 12 | AI20: =YEAR(D20) -> 2021
A21: MAE003 | B21: =iferror(VLOOKUP((LEFT(A21,6)),CUSTOMER_DETAILS,2,FALSE),"-") -> SHREE GAYATRI PACKAGING | C21: - | D21: 44551 | E21: - | F21: - | G21: - | H21: - | I21: - | J21: =D21 -> 44551 | K21: 22 | L21: - | M21: TRUCK | N21: SELDOH NAGPUR | O21: - | Q21: BIOMASS PELLET 06MM | R21: =IFERROR(VLOOKUP(Q21,'PRODUCT TABLE'!$A$2:$B$26,2,FALSE),"-") -> 44011090 | S21: 1000 | T21: 10.5 | U21: KG | V21: =S21*T21 -> 10500 | W21: 0.025 | X21: 0.025 | Y21: 0 | Z21: =IF(((ROUNDUP((AG21+V21),0))-(AG21+V21))>0.49,ROUNDdown((AG21+V21),0),ROUNDup((AG21+V21),0)) + AB21 -> 11025 | AA21: =Z21-(V21+AG21 + AB21) -> 0 | AC21: =V21 -> 10500 | AD21: =AC21*W21 -> 262.5 | AE21: =AC21*X21 -> 262.5 | AF21: =AC21*Y21 -> 0 | AG21: =SUM(AD21:AF21) -> 525 | AH21: =IFERROR(MONTH(D21)," ") -> 12 | AI21: =YEAR(D21) -> 2021
A22: MAE010 | B22: =iferror(VLOOKUP((LEFT(A22,6)),CUSTOMER_DETAILS,2,FALSE),"-") -> KRISHNA ENTERPRISES | C22: - | D22: 44563 | E22: - | F22: - | G22: - | H22: - | I22: - | J22: =D22 -> 44563 | K22: 23 | L22: - | M22: TRUCK | N22: NAGPUR | O22: - | Q22: BIOMASS PELLET 06MM | R22: =IFERROR(VLOOKUP(Q22,'PRODUCT TABLE'!$A$2:$B$26,2,FALSE),"-") -> 44011090 | S22: 2100 | T22: 10.5 | U22: KG | V22: =S22*T22 -> 22050 | W22: 0.025 | X22: 0.025 | Y22: 0 | Z22: =IF(((ROUNDUP((AG22+V22),0))-(AG22+V22))>0.49,ROUNDdown((AG22+V22),0),ROUNDup((AG22+V22),0)) + AB22 -> 23152 | AA22: =Z22-(V22+AG22 + AB22) -> -0.5 | AC22: =V22 -> 22050 | AD22: =AC22*W22 -> 551.25 | AE22: =AC22*X22 -> 551.25 | AF22: =AC22*Y22 -> 0 | AG22: =SUM(AD22:AF22) -> 1102.5 | AH22: =IFERROR(MONTH(D22)," ") -> 1 | AI22: =YEAR(D22) -> 2022
A23: MAE010 | B23: =iferror(VLOOKUP((LEFT(A23,6)),CUSTOMER_DETAILS,2,FALSE),"-") -> KRISHNA ENTERPRISES | C23: - | D23: 44563 | E23: - | F23: - | G23: - | H23: - | I23: - | J23: =D23 -> 44563 | K23: 24 | L23: - | M23: TRUCK | N23: NAGPUR | O23: - | Q23: BIOMASS PELLET 06MM | R23: =IFERROR(VLOOKUP(Q23,'PRODUCT TABLE'!$A$2:$B$26,2,FALSE),"-") -> 44011090 | S23: 5550 | T23: 7.3 | U23: KG | V23: =S23*T23 -> 40515 | W23: 0.025 | X23: 0.025 | Y23: 0 | Z23: =IF(((ROUNDUP((AG23+V23),0))-(AG23+V23))>0.49,ROUNDdown((AG23+V23),0),ROUNDup((AG23+V23),0)) + AB23 -> 42541 | AA23: =Z23-(V23+AG23 + AB23) -> 0.25 | AC23: =V23 -> 40515 | AD23: =AC23*W23 -> 1012.875 | AE23: =AC23*X23 -> 1012.875 | AF23: =AC23*Y23 -> 0 | AG23: =SUM(AD23:AF23) -> 2025.75 | AH23: =IFERROR(MONTH(D23)," ") -> 1 | AI23: =YEAR(D23) -> 2022
A24: MAE | B24: PAVITRA FABRIC TAPE INDUSTRIES | C24: - | D24: 44570 | E24: - | F24: - | G24: - | H24: - | I24: - | J24: =D24 -> 44570 | K24: 25 | L24: - | M24: TRUCK | N24: HINGNA NAGPUR | O24: - | Q24: BIOMASS PELLET 06MM | R24: =IFERROR(VLOOKUP(Q24,'PRODUCT TABLE'!$A$2:$B$26,2,FALSE),"-") -> 44011090 | S24: 210 | T24: 11.5 | U24: KG | V24: =S24*T24 -> 2415 | W24: 0.025 | X24: 0.025 | Y24: 0 | Z24: =IF(((ROUNDUP((AG24+V24),0))-(AG24+V24))>0.49,ROUNDdown((AG24+V24),0),ROUNDup((AG24+V24),0)) + AB24 -> 2536 | AA24: =Z24-(V24+AG24 + AB24) -> 0.25 | AC24: =V24 -> 2415 | AD24: =AC24*W24 -> 60.375 | AE24: =AC24*X24 -> 60.375 | AF24: =AC24*Y24 -> 0 | AG24: =SUM(AD24:AF24) -> 120.75 | AH24: =IFERROR(MONTH(D24)," ") -> 1 | AI24: =YEAR(D24) -> 2022
A25: MAE | B25: PAVITRA FABRIC TAPE INDUSTRIES | C25: - | D25: 44577 | E25: - | F25: - | G25: - | H25: - | I25: - | J25: =D25 -> 44577 | K25: 26 | L25: - | M25: TRUCK | N25: HINGNA NAGPUR | O25: - | Q25: BIOMASS PELLET 06MM | R25: =IFERROR(VLOOKUP(Q25,'PRODUCT TABLE'!$A$2:$B$26,2,FALSE),"-") -> 44011090 | S25: 1020 | T25: 11 | U25: KG | V25: =S25*T25 -> 11220 | W25: 0.025 | X25: 0.025 | Y25: 0 | Z25: =IF(((ROUNDUP((AG25+V25),0))-(AG25+V25))>0.49,ROUNDdown((AG25+V25),0),ROUNDup((AG25+V25),0)) + AB25 -> 11781 | AA25: =Z25-(V25+AG25 + AB25) -> 0 | AC25: =V25 -> 11220 | AD25: =AC25*W25 -> 280.5 | AE25: =AC25*X25 -> 280.5 | AF25: =AC25*Y25 -> 0 | AG25: =SUM(AD25:AF25) -> 561 | AH25: =IFERROR(MONTH(D25)," ") -> 1 | AI25: =YEAR(D25) -> 2022
A26: MAE | B26: PAVITRA FABRIC TAPE INDUSTRIES | C26: - | D26: 44592 | E26: - | F26: - | G26: - | H26: - | I26: - | J26: =D26 -> 44592 | K26: 27 | L26: - | M26: TRUCK | N26: HINGNA NAGPUR | O26: - | Q26: BIOMASS PELLET 06MM | R26: =IFERROR(VLOOKUP(Q26,'PRODUCT TABLE'!$A$2:$B$26,2,FALSE),"-") -> 44011090 | S26: 1020 | T26: 11 | U26: KG | V26: =S26*T26 -> 11220 | W26: 0.025 | X26: 0.025 | Y26: 0 | Z26: =IF(((ROUNDUP((AG26+V26),0))-(AG26+V26))>0.49,ROUNDdown((AG26+V26),0),ROUNDup((AG26+V26),0)) + AB26 -> 11781 | AA26: =Z26-(V26+AG26 + AB26) -> 0 | AC26: =V26 -> 11220 | AD26: =AC26*W26 -> 280.5 | AE26: =AC26*X26 -> 280.5 | AF26: =AC26*Y26 -> 0 | AG26: =SUM(AD26:AF26) -> 561 | AH26: =IFERROR(MONTH(D26)," ") -> 1 | AI26: =YEAR(D26) -> 2022
A27: MAE | B27: PAVITRA FABRIC TAPE INDUSTRIES | C27: - | D27: 44602 | E27: - | F27: - | G27: - | H27: - | I27: - | J27: =D27 -> 44602 | K27: 28 | L27: - | M27: TRUCK | N27: HINGNA NAGPUR | O27: - | Q27: BIOMASS PELLET 06MM | R27: =IFERROR(VLOOKUP(Q27,'PRODUCT TABLE'!$A$2:$B$26,2,FALSE),"-") -> 44011090 | S27: 1020 | T27: 11 | U27: KG | V27: =S27*T27 -> 11220 | W27: 0.025 | X27: 0.025 | Y27: 0 | Z27: =IF(((ROUNDUP((AG27+V27),0))-(AG27+V27))>0.49,ROUNDdown((AG27+V27),0),ROUNDup((AG27+V27),0)) + AB27 -> 11781 | AA27: =Z27-(V27+AG27 + AB27) -> 0 | AC27: =V27 -> 11220 | AD27: =AC27*W27 -> 280.5 | AE27: =AC27*X27 -> 280.5 | AF27: =AC27*Y27 -> 0 | AG27: =SUM(AD27:AF27) -> 561 | AH27: =IFERROR(MONTH(D27)," ") -> 2 | AI27: =YEAR(D27) -> 2022
A28: MAE003 | B28: =iferror(VLOOKUP((LEFT(A28,6)),CUSTOMER_DETAILS,2,FALSE),"-") -> SHREE GAYATRI PACKAGING | C28: - | D28: 44610 | E28: - | F28: - | G28: - | H28: - | I28: - | J28: =D28 -> 44610 | K28: 29 | L28: - | M28: TRUCK | N28: SELDOH NAGPUR | O28: - | Q28: BIOMASS PELLET 06MM | R28: =IFERROR(VLOOKUP(Q28,'PRODUCT TABLE'!$A$2:$B$26,2,FALSE),"-") -> 44011090 | S28: 2100 | T28: 10.5 | U28: KG | V28: =S28*T28 -> 22050 | W28: 0.025 | X28: 0.025 | Y28: 0 | Z28: =IF(((ROUNDUP((AG28+V28),0))-(AG28+V28))>0.49,ROUNDdown((AG28+V28),0),ROUNDup((AG28+V28),0)) + AB28 -> 23152 | AA28: =Z28-(V28+AG28 + AB28) -> -0.5 | AC28: =V28 -> 22050 | AD28: =AC28*W28 -> 551.25 | AE28: =AC28*X28 -> 551.25 | AF28: =AC28*Y28 -> 0 | AG28: =SUM(AD28:AF28) -> 1102.5 | AH28: =IFERROR(MONTH(D28)," ") -> 2 | AI28: =YEAR(D28) -> 2022
A29: MAE | B29: PAVITRA FABRIC TAPE INDUSTRIES | C29: - | D29: 44612 | E29: - | F29: - | G29: - | H29: - | I29: - | J29: =D29 -> 44612 | K29: 30 | L29: - | M29: TRUCK | N29: HINGNA NAGPUR | O29: - | Q29: BIOMASS PELLET 06MM | R29: =IFERROR(VLOOKUP(Q29,'PRODUCT TABLE'!$A$2:$B$26,2,FALSE),"-") -> 44011090 | S29: 1020 | T29: 11 | U29: KG | V29: =S29*T29 -> 11220 | W29: 0.025 | X29: 0.025 | Y29: 0 | Z29: =IF(((ROUNDUP((AG29+V29),0))-(AG29+V29))>0.49,ROUNDdown((AG29+V29),0),ROUNDup((AG29+V29),0)) + AB29 -> 11781 | AA29: =Z29-(V29+AG29 + AB29) -> 0 | AC29: =V29 -> 11220 | AD29: =AC29*W29 -> 280.5 | AE29: =AC29*X29 -> 280.5 | AF29: =AC29*Y29 -> 0 | AG29: =SUM(AD29:AF29) -> 561 | AH29: =IFERROR(MONTH(D29)," ") -> 2 | AI29: =YEAR(D29) -> 2022
A30: MAE007 | B30: =iferror(VLOOKUP((LEFT(A30,6)),CUSTOMER_DETAILS,2,FALSE),"-") -> KABRA FOODS | C30: - | D30: 44616 | E30: - | F30: - | G30: - | H30: - | I30: - | J30: =D30 -> 44616 | K30: 31 | L30: - | M30: TRUCK | N30: JALGAO MH | O30: - | Q30: BIOMASS PELLET 06MM | R30: =IFERROR(VLOOKUP(Q30,'PRODUCT TABLE'!$A$2:$B$26,2,FALSE),"-") -> 44011090 | S30: 300 | T30: 10.8 | U30: KG | V30: =S30*T30 -> 3240 | W30: 0.025 | X30: 0.025 | Y30: 0 | Z30: =IF(((ROUNDUP((AG30+V30),0))-(AG30+V30))>0.49,ROUNDdown((AG30+V30),0),ROUNDup((AG30+V30),0)) + AB30 -> 3402 | AA30: =Z30-(V30+AG30 + AB30) -> 0 | AC30: =V30 -> 3240 | AD30: =AC30*W30 -> 81 | AE30: =AC30*X30 -> 81 | AF30: =AC30*Y30 -> 0 | AG30: =SUM(AD30:AF30) -> 162 | AH30: =IFERROR(MONTH(D30)," ") -> 2 | AI30: =YEAR(D30) -> 2022
A31: MAE010 | B31: =iferror(VLOOKUP((LEFT(A31,6)),CUSTOMER_DETAILS,2,FALSE),"-") -> KRISHNA ENTERPRISES | C31: - | D31: 44617 | E31: - | F31: - | G31: - | H31: - | I31: - | J31: =D31 -> 44617 | K31: 32 | L31: - | M31: TRUCK | N31: NAGPUR | O31: - | Q31: BIOMASS PELLET 06MM | R31: =IFERROR(VLOOKUP(Q31,'PRODUCT TABLE'!$A$2:$B$26,2,FALSE),"-") -> 44011090 | S31: 5100 | T31: 10.5 | U31: KG | V31: =S31*T31 -> 53550 | W31: 0.025 | X31: 0.025 | Y31: 0 | Z31: =IF(((ROUNDUP((AG31+V31),0))-(AG31+V31))>0.49,ROUNDdown((AG31+V31),0),ROUNDup((AG31+V31),0)) + AB31 -> 56227 | AA31: =Z31-(V31+AG31 + AB31) -> -0.5 | AC31: =V31 -> 53550 | AD31: =AC31*W31 -> 1338.75 | AE31: =AC31*X31 -> 1338.75 | AF31: =AC31*Y31 -> 0 | AG31: =SUM(AD31:AF31) -> 2677.5 | AH31: =IFERROR(MONTH(D31)," ") -> 2 | AI31: =YEAR(D31) -> 2022
A32: MAE | B32: PRABHAT ENTERPRISES | C32: - | D32: 44631 | E32: - | F32: - | G32: - | H32: - | I32: - | J32: =D32 -> 44631 | K32: 34 | L32: - | M32: TRUCK | N32: BHAYANDER MH | O32: - | Q32: BIOMASS PELLET 06MM | R32: =IFERROR(VLOOKUP(Q32,'PRODUCT TABLE'!$A$2:$B$26,2,FALSE),"-") -> 44011090 | S32: 300 | T32: 6 | U32: KG | V32: =S32*T32 -> 1800 | W32: 0.025 | X32: 0.025 | Y32: 0 | Z32: =IF(((ROUNDUP((AG32+V32),0))-(AG32+V32))>0.49,ROUNDdown((AG32+V32),0),ROUNDup((AG32+V32),0)) + AB32 -> 1890 | AA32: =Z32-(V32+AG32 + AB32) -> 0 | AC32: =V32 -> 1800 | AD32: =AC32*W32 -> 45 | AE32: =AC32*X32 -> 45 | AF32: =AC32*Y32 -> 0 | AG32: =SUM(AD32:AF32) -> 90 | AH32: =IFERROR(MONTH(D32)," ") -> 3 | AI32: =YEAR(D32) -> 2022
A33: MAE003 | B33: =iferror(VLOOKUP((LEFT(A33,6)),CUSTOMER_DETAILS,2,FALSE),"-") -> SHREE GAYATRI PACKAGING | C33: - | D33: 44642 | E33: - | F33: - | G33: - | H33: - | I33: - | J33: =D33 -> 44642 | K33: 35 | L33: - | M33: TRUCK | N33: SELDOH NAGPUR | O33: - | Q33: BIOMASS PELLET 06MM | R33: =IFERROR(VLOOKUP(Q33,'PRODUCT TABLE'!$A$2:$B$26,2,FALSE),"-") -> 44011090 | S33: 1020 | T33: 12 | U33: KG | V33: =S33*T33 -> 12240 | W33: 0.025 | X33: 0.025 | Y33: 0 | Z33: =IF(((ROUNDUP((AG33+V33),0))-(AG33+V33))>0.49,ROUNDdown((AG33+V33),0),ROUNDup((AG33+V33),0)) + AB33 -> 12852 | AA33: =Z33-(V33+AG33 + AB33) -> 0 | AC33: =V33 -> 12240 | AD33: =AC33*W33 -> 306 | AE33: =AC33*X33 -> 306 | AF33: =AC33*Y33 -> 0 | AG33: =SUM(AD33:AF33) -> 612 | AH33: =IFERROR(MONTH(D33)," ") -> 3 | AI33: =YEAR(D33) -> 2022
A34: MAE010 | B34: =iferror(VLOOKUP((LEFT(A34,6)),CUSTOMER_DETAILS,2,FALSE),"-") -> KRISHNA ENTERPRISES | C34: - | D34: 44644 | E34: - | F34: - | G34: - | H34: - | I34: - | J34: =D34 -> 44644 | K34: 36 | L34: - | M34: TRUCK | N34: NAGPUR | O34: - | Q34: BIOMASS PELLET 06MM | R34: =IFERROR(VLOOKUP(Q34,'PRODUCT TABLE'!$A$2:$B$26,2,FALSE),"-") -> 44011090 | S34: 7020 | T34: 10.9 | U34: KG | V34: =S34*T34 -> 76518 | W34: 0.025 | X34: 0.025 | Y34: 0 | Z34: =IF(((ROUNDUP((AG34+V34),0))-(AG34+V34))>0.49,ROUNDdown((AG34+V34),0),ROUNDup((AG34+V34),0)) + AB34 -> 80344 | AA34: =Z34-(V34+AG34 + AB34) -> 0.1 | AC34: =V34 -> 76518 | AD34: =AC34*W34 -> 1912.95 | AE34: =AC34*X34 -> 1912.95 | AF34: =AC34*Y34 -> 0 | AG34: =SUM(AD34:AF34) -> 3825.9 | AH34: =IFERROR(MONTH(D34)," ") -> 3 | AI34: =YEAR(D34) -> 2022
A35: MAE010 | B35: =iferror(VLOOKUP((LEFT(A35,6)),CUSTOMER_DETAILS,2,FALSE),"-") -> KRISHNA ENTERPRISES | C35: - | D35: 44649 | E35: - | F35: - | G35: - | H35: - | I35: - | J35: =D35 -> 44649 | K35: 37 | L35: - | M35: TRUCK | N35: NAGPUR | O35: - | Q35: BIOMASS PELLET 06MM | R35: =IFERROR(VLOOKUP(Q35,'PRODUCT TABLE'!$A$2:$B$26,2,FALSE),"-") -> 44011090 | S35: 4600 | T35: 11 | U35: KG | V35: =S35*T35 -> 50600 | W35: 0.025 | X35: 0.025 | Y35: 0 | Z35: =IF(((ROUNDUP((AG35+V35),0))-(AG35+V35))>0.49,ROUNDdown((AG35+V35),0),ROUNDup((AG35+V35),0)) + AB35 -> 53130 | AA35: =Z35-(V35+AG35 + AB35) -> 0 | AC35: =V35 -> 50600 | AD35: =AC35*W35 -> 1265 | AE35: =AC35*X35 -> 1265 | AF35: =AC35*Y35 -> 0 | AG35: =SUM(AD35:AF35) -> 2530 | AH35: =IFERROR(MONTH(D35)," ") -> 3 | AI35: =YEAR(D35) -> 2022
A36: MAE005/22-23/01 | B36: AEC PLAST | C36: - | D36: 44653 | E36: - | F36: - | G36: - | H36: - | I36: - | J36: =D36 -> 44653 | K36: 38 | L36: - | M36: TRUCK | N36: BUTIBORI MIDC | O36: - | Q36: BIOMASS BRIQUETTE 90MM | R36: =IFERROR(VLOOKUP(Q36,'PRODUCT TABLE'!$A$2:$B$26,2,FALSE),"-") -> 44011090 | S36: 10020 | T36: 5.7 | U36: KG | V36: =S36*T36 -> 57114 | W36: 0.025 | X36: 0.025 | Y36: 0 | Z36: =IF(((ROUNDUP((AG36+V36),0))-(AG36+V36))>0.49,ROUNDdown((AG36+V36),0),ROUNDup((AG36+V36),0)) + AB36 -> 59970 | AA36: =Z36-(V36+AG36 + AB36) -> 0.3 | AC36: =V36 -> 57114 | AD36: =AC36*W36 -> 1427.85 | AE36: =AC36*X36 -> 1427.85 | AF36: =AC36*Y36 -> 0 | AG36: =SUM(AD36:AF36) -> 2855.7 | AH36: =IFERROR(MONTH(D36)," ") -> 4 | AI36: =YEAR(D36) -> 2022
A37: MAE003/22-23/02 | B37: =iferror(VLOOKUP((LEFT(A37,6)),CUSTOMER_DETAILS,2,FALSE),"-") -> SHREE GAYATRI PACKAGING | C37: - | D37: 44661 | E37: - | F37: - | G37: - | H37: - | I37: - | J37: =D37 -> 44661 | K37: 39 | L37: - | M37: TRUCK | N37: SELDOH NAGPUR | O37: - | Q37: BIOMASS PELLET 06MM | R37: =IFERROR(VLOOKUP(Q37,'PRODUCT TABLE'!$A$2:$B$26,2,FALSE),"-") -> 44011090 | S37: 1500 | T37: 12 | U37: KG | V37: =S37*T37 -> 18000 | W37: 0.025 | X37: 0.025 | Y37: 0 | Z37: =IF(((ROUNDUP((AG37+V37),0))-(AG37+V37))>0.49,ROUNDdown((AG37+V37),0),ROUNDup((AG37+V37),0)) + AB37 -> 18900 | AA37: =Z37-(V37+AG37 + AB37) -> 0 | AC37: =V37 -> 18000 | AD37: =AC37*W37 -> 450 | AE37: =AC37*X37 -> 450 | AF37: =AC37*Y37 -> 0 | AG37: =SUM(AD37:AF37) -> 900 | AH37: =IFERROR(MONTH(D37)," ") -> 4 | AI37: =YEAR(D37) -> 2022
A38: MAE010/22-23/03 | B38: =iferror(VLOOKUP((LEFT(A38,6)),CUSTOMER_DETAILS,2,FALSE),"-") -> KRISHNA ENTERPRISES | C38: - | D38: 44667 | E38: - | F38: - | G38: - | H38: - | I38: - | J38: =D38 -> 44667 | K38: 40 | L38: - | M38: TRUCK | N38: NAGPUR | O38: - | Q38: BIOMASS PELLET 06MM | R38: =IFERROR(VLOOKUP(Q38,'PRODUCT TABLE'!$A$2:$B$26,2,FALSE),"-") -> 44011090 | S38: 7530 | T38: 11 | U38: KG | V38: =S38*T38 -> 82830 | W38: 0.025 | X38: 0.025 | Y38: 0 | Z38: =IF(((ROUNDUP((AG38+V38),0))-(AG38+V38))>0.49,ROUNDdown((AG38+V38),0),ROUNDup((AG38+V38),0)) + AB38 -> 86971 | AA38: =Z38-(V38+AG38 + AB38) -> -0.5 | AC38: =V38 -> 82830 | AD38: =AC38*W38 -> 2070.75 | AE38: =AC38*X38 -> 2070.75 | AF38: =AC38*Y38 -> 0 | AG38: =SUM(AD38:AF38) -> 4141.5 | AH38: =IFERROR(MONTH(D38)," ") -> 4 | AI38: =YEAR(D38) -> 2022
